<?xml version="1.0" encoding="utf-8"?>
<!-- =================================================================================== -->
<!-- |    This document was autogenerated by xacro from mirror.urdf.xacro              | -->
<!-- |    EDITING THIS FILE BY HAND IS NOT RECOMMENDED                                 | -->
<!-- =================================================================================== -->
<robot name="mirror">
  <!-- 
  ROS urdf definition of the MIRROR robot
  
  Author: Gennaro Raiola
-->
  <!-- scaling facto for available peack torque link side, from 0 to 1 -->
  <material name="black">
    <color rgba="0.4 0.4 0.4 1"/>
  </material>
  <material name="dark">
    <color rgba="0.1 0.1 0.1 1"/>
  </material>
  <link name="base_link"/>
  <link name="core_link">
    <inertial>
      <origin rpy="0.0 0.0 0.0" xyz="-0.0043987232 0.0018940942 0.13026949"/>
      <mass value="2.7122273e+01"/>
      <inertia ixx="184.06228" ixy="-1.5422487" ixz="-2.4577787" iyy="557.46316" iyz="0.47296856" izz="433.94211"/>
    </inertial>
    <visual>
      <origin rpy="0 0 0" xyz="0 0 0"/>
      <material name="black"/>
      <geometry name="core_visual">
        <mesh filename="package://mirror_urdf/meshes/mesh_base.stl" scale="0.001 0.001 0.001"/>
      </geometry>
    </visual>
    <collision>
      <origin rpy="0 0 0" xyz="0 0 0"/>
      <geometry name="core_collision">
        <mesh filename="package://mirror_urdf/meshes/mesh_base_collision.stl" scale="0.001 0.001 0.001"/>
      </geometry>
    </collision>
  </link>
  <joint name="base_joint" type="fixed">
    <parent link="base_link"/>
    <child link="core_link"/>
    <origin rpy="0 0 0" xyz="0 0 0"/>
  </joint>
  <!-- LINKS -->
  <link name="arm_1_link_1">
    <inertial>
      <origin rpy="0 0 0" xyz="0.0013955428 0.025982581 -0.16511476"/>
      <mass value="5.9029271e+00"/>
      <inertia ixx="0.062182861" ixy="8.1614096e-05" ixz="0.00010385066" iyy="0.055346023" iyz="0.01299992" izz="0.016821722"/>
    </inertial>
    <visual>
      <origin rpy="0 0 0" xyz="0 0 0"/>
      <geometry name="arm_1_link_1_visual">
        <mesh filename="package://mirror_urdf/meshes/mesh_link1.stl" scale="0.001 0.001 0.001"/>
      </geometry>
      <material name="black"/>
    </visual>
    <collision>
      <origin rpy="0 0 0" xyz="0 0 0"/>
      <geometry name="arm_1_link_1_collision">
        <mesh filename="package://mirror_urdf/meshes/mesh_link1_collision.stl" scale="0.001 0.001 0.001"/>
      </geometry>
    </collision>
  </link>
  <link name="arm_1_link_2">
    <inertial>
      <origin rpy="0 0 0" xyz="0.0 -0.0071720374 -0.20000694"/>
      <mass value="1.9989653e+00"/>
      <inertia ixx="0.049589547" ixy="-2.3822174e-08" ixz="0.00023476881" iyy="0.051111593" iyz="7.769849e-07" izz="0.0040702979"/>
    </inertial>
    <visual>
      <origin rpy="0 0 0" xyz="0 0 0"/>
      <geometry name="{prefix}_link_2_visual">
        <mesh filename="package://mirror_urdf/meshes/mesh_link2.stl" scale="0.001 0.001 0.001"/>
      </geometry>
      <material name="black"/>
    </visual>
    <collision>
      <origin rpy="0 0 0" xyz="0 0 0"/>
      <geometry name="{prefix}_link_2_collision">
        <mesh filename="package://mirror_urdf/meshes/mesh_link2_collision.stl" scale="0.001 0.001 0.001"/>
      </geometry>
    </collision>
  </link>
  <link name="arm_1_link_3">
    <inertial>
      <origin rpy="0 0 0" xyz="-0.0021052916 -0.10638552 -0.074903486"/>
      <mass value="5.8838845e+00"/>
      <inertia ixx="0.061043599" ixy="-0.00015340891" ixz="-0.0001783316" iyy="0.05360131" iyz="-0.0110909" izz="0.017380798"/>
    </inertial>
    <visual>
      <origin rpy="0 0 0" xyz="0 0 0"/>
      <geometry name="arm_1_link_3_visual">
        <mesh filename="package://mirror_urdf/meshes/mesh_link3.stl" scale="0.001 0.001 0.001"/>
      </geometry>
      <material name="black"/>
    </visual>
    <collision>
      <origin rpy="0 0 0" xyz="0 0 0"/>
      <geometry name="arm_1_link_3_collision">
        <mesh filename="package://mirror_urdf/meshes/mesh_link3_collision.stl" scale="0.001 0.001 0.001"/>
      </geometry>
    </collision>
  </link>
  <link name="arm_1_link_4">
    <inertial>
      <origin rpy="0 0 0" xyz="0.00024496086 -0.0010728501 -0.049015064"/>
      <mass value="1.3982240e+00"/>
      <inertia ixx="0.01466727" ixy="-2.0411012e-05" ixz="-4.476957e-05" iyy="0.0086598581" iyz="-8.3199044e-05" izz="0.010450923"/>
    </inertial>
    <visual>
      <origin rpy="0 0 0" xyz="0 0 0"/>
      <geometry name="arm_1_link_4_visual">
        <mesh filename="package://mirror_urdf/meshes/mesh_link4.stl" scale="0.001 0.001 0.001"/>
      </geometry>
      <material name="black"/>
    </visual>
    <collision>
      <origin rpy="0 0 0" xyz="0 0 0"/>
      <geometry name="arm_1_link_4_collision">
        <mesh filename="package://mirror_urdf/meshes/mesh_link4_collision.stl" scale="0.001 0.001 0.001"/>
      </geometry>
    </collision>
  </link>
  <link name="arm_1_link_5">
    <inertial>
      <origin rpy="0 0 0" xyz="-0.0013228834 -0.08468301 -0.053211105"/>
      <mass value="5.7923846e+00"/>
      <inertia ixx="0.055109543" ixy="-0.00014003837" ixz="0.00021470743" iyy="0.051309424" iyz="-0.0010289246" izz="0.013804762"/>
    </inertial>
    <visual>
      <origin rpy="0 0 0" xyz="0 0 0"/>
      <geometry name="arm_1_link_5_visual">
        <mesh filename="package://mirror_urdf/meshes/mesh_link5.stl" scale="0.001 0.001 0.001"/>
      </geometry>
      <material name="black"/>
    </visual>
    <collision>
      <origin rpy="0 0 0" xyz="0 0 0"/>
      <geometry name="arm_1_link_5_collision">
        <mesh filename="package://mirror_urdf/meshes/mesh_link5_collision.stl" scale="0.001 0.001 0.001"/>
      </geometry>
    </collision>
  </link>
  <link name="arm_1_link_6">
    <inertial>
      <origin rpy="0 0 0" xyz="-0.0015850697 0.027619818 -0.025442753"/>
      <mass value="1.1947654e+00"/>
      <inertia ixx="0.012632056" ixy="0.00021474114" ixz="0.0001764965" iyy="0.0098149674" iyz="-0.0035702374" izz="0.0072417288"/>
    </inertial>
    <visual>
      <origin rpy="0 0 0" xyz="0 0 0"/>
      <geometry name="arm_1_link_6_visual">
        <mesh filename="package://mirror_urdf/meshes/mesh_link6.stl" scale="0.001 0.001 0.001"/>
      </geometry>
      <material name="black"/>
    </visual>
    <collision>
      <origin rpy="0 0 0" xyz="0 0 0"/>
      <geometry name="arm_1_link_6_collision">
        <box size="0.12 0.12 0.25"/>
        <!-- note: better for simulation -->
      </geometry>
    </collision>
  </link>
  <link name="arm_1_TCP"/>
  <!-- JOINTS MISSING INFO limits friction and damping-->
  <joint name="arm_1_joint_1" type="revolute">
    <parent link="core_link"/>
    <child link="arm_1_link_1"/>
    <origin rpy="0.0 0.0 0.0" xyz="0.342694 0.0 0.1338"/>
    <axis xyz="0 0 -1"/>
    <limit effort="200.0" lower="-2.70526034059" upper="2.70526034059" velocity="6.283"/>
    <dynamics damping="3.0" friction="0"/>
  </joint>
  <joint name="arm_1_joint_2" type="revolute">
    <parent link="arm_1_link_1"/>
    <child link="arm_1_link_2"/>
    <origin rpy="0 0 0" xyz="0 0.13166 -0.24966"/>
    <axis xyz="0 1 0"/>
    <limit effort="200.0" lower="-2.70526034059" upper="2.70526034059" velocity="6.283"/>
    <dynamics damping="3.0" friction="0"/>
  </joint>
  <joint name="arm_1_joint_3" type="revolute">
    <parent link="arm_1_link_2"/>
    <child link="arm_1_link_3"/>
    <origin rpy="0 0 0" xyz="0 0 -0.4"/>
    <axis xyz="0 -1 0"/>
    <limit effort="200.0" lower="-2.70526034059" upper="2.70526034059" velocity="6.283"/>
    <dynamics damping="3.0" friction="0"/>
  </joint>
  <joint name="arm_1_joint_4" type="revolute">
    <parent link="arm_1_link_3"/>
    <child link="arm_1_link_4"/>
    <origin rpy="0 0 0" xyz="0 -0.13166 -0.24966"/>
    <axis xyz="0 0 -1"/>
    <limit effort="200.0" lower="-2.70526034059" upper="2.70526034059" velocity="6.283"/>
    <dynamics damping="3.0" friction="0"/>
  </joint>
  <joint name="arm_1_joint_5" type="revolute">
    <parent link="arm_1_link_4"/>
    <child link="arm_1_link_5"/>
    <origin rpy="0 0 0" xyz="0 0.08816 -0.1535"/>
    <axis xyz="0 1 0"/>
    <limit effort="200.0" lower="-1.18682389136" upper="1.18682389136" velocity="6.283"/>
    <dynamics damping="3.0" friction="0"/>
  </joint>
  <joint name="arm_1_joint_6" type="revolute">
    <parent link="arm_1_link_5"/>
    <child link="arm_1_link_6"/>
    <origin rpy="0 0 0" xyz="0 -0.08816 -0.22216"/>
    <axis xyz="0 0 -1"/>
    <limit effort="200.0" lower="-2.70526034059" upper="2.70526034059" velocity="6.283"/>
    <dynamics damping="3.0" friction="0"/>
  </joint>
  <joint name="arm_1_joint_TCP" type="fixed">
    <parent link="arm_1_link_6"/>
    <child link="arm_1_TCP"/>
    <origin rpy="0 0 0" xyz="0 0 -0.14"/>
  </joint>
  <!-- LINKS -->
  <link name="arm_2_link_1">
    <inertial>
      <origin rpy="0 0 0" xyz="0.0013955428 0.025982581 -0.16511476"/>
      <mass value="5.9029271e+00"/>
      <inertia ixx="0.062182861" ixy="8.1614096e-05" ixz="0.00010385066" iyy="0.055346023" iyz="0.01299992" izz="0.016821722"/>
    </inertial>
    <visual>
      <origin rpy="0 0 0" xyz="0 0 0"/>
      <geometry name="arm_2_link_1_visual">
        <mesh filename="package://mirror_urdf/meshes/mesh_link1.stl" scale="0.001 0.001 0.001"/>
      </geometry>
      <material name="black"/>
    </visual>
    <collision>
      <origin rpy="0 0 0" xyz="0 0 0"/>
      <geometry name="arm_2_link_1_collision">
        <mesh filename="package://mirror_urdf/meshes/mesh_link1_collision.stl" scale="0.001 0.001 0.001"/>
      </geometry>
    </collision>
  </link>
  <link name="arm_2_link_2">
    <inertial>
      <origin rpy="0 0 0" xyz="0.0 -0.0071720374 -0.20000694"/>
      <mass value="1.9989653e+00"/>
      <inertia ixx="0.049589547" ixy="-2.3822174e-08" ixz="0.00023476881" iyy="0.051111593" iyz="7.769849e-07" izz="0.0040702979"/>
    </inertial>
    <visual>
      <origin rpy="0 0 0" xyz="0 0 0"/>
      <geometry name="{prefix}_link_2_visual">
        <mesh filename="package://mirror_urdf/meshes/mesh_link2.stl" scale="0.001 0.001 0.001"/>
      </geometry>
      <material name="black"/>
    </visual>
    <collision>
      <origin rpy="0 0 0" xyz="0 0 0"/>
      <geometry name="{prefix}_link_2_collision">
        <mesh filename="package://mirror_urdf/meshes/mesh_link2_collision.stl" scale="0.001 0.001 0.001"/>
      </geometry>
    </collision>
  </link>
  <link name="arm_2_link_3">
    <inertial>
      <origin rpy="0 0 0" xyz="-0.0021052916 -0.10638552 -0.074903486"/>
      <mass value="5.8838845e+00"/>
      <inertia ixx="0.061043599" ixy="-0.00015340891" ixz="-0.0001783316" iyy="0.05360131" iyz="-0.0110909" izz="0.017380798"/>
    </inertial>
    <visual>
      <origin rpy="0 0 0" xyz="0 0 0"/>
      <geometry name="arm_2_link_3_visual">
        <mesh filename="package://mirror_urdf/meshes/mesh_link3.stl" scale="0.001 0.001 0.001"/>
      </geometry>
      <material name="black"/>
    </visual>
    <collision>
      <origin rpy="0 0 0" xyz="0 0 0"/>
      <geometry name="arm_2_link_3_collision">
        <mesh filename="package://mirror_urdf/meshes/mesh_link3_collision.stl" scale="0.001 0.001 0.001"/>
      </geometry>
    </collision>
  </link>
  <link name="arm_2_link_4">
    <inertial>
      <origin rpy="0 0 0" xyz="0.00024496086 -0.0010728501 -0.049015064"/>
      <mass value="1.3982240e+00"/>
      <inertia ixx="0.01466727" ixy="-2.0411012e-05" ixz="-4.476957e-05" iyy="0.0086598581" iyz="-8.3199044e-05" izz="0.010450923"/>
    </inertial>
    <visual>
      <origin rpy="0 0 0" xyz="0 0 0"/>
      <geometry name="arm_2_link_4_visual">
        <mesh filename="package://mirror_urdf/meshes/mesh_link4.stl" scale="0.001 0.001 0.001"/>
      </geometry>
      <material name="black"/>
    </visual>
    <collision>
      <origin rpy="0 0 0" xyz="0 0 0"/>
      <geometry name="arm_2_link_4_collision">
        <mesh filename="package://mirror_urdf/meshes/mesh_link4_collision.stl" scale="0.001 0.001 0.001"/>
      </geometry>
    </collision>
  </link>
  <link name="arm_2_link_5">
    <inertial>
      <origin rpy="0 0 0" xyz="-0.0013228834 -0.08468301 -0.053211105"/>
      <mass value="5.7923846e+00"/>
      <inertia ixx="0.055109543" ixy="-0.00014003837" ixz="0.00021470743" iyy="0.051309424" iyz="-0.0010289246" izz="0.013804762"/>
    </inertial>
    <visual>
      <origin rpy="0 0 0" xyz="0 0 0"/>
      <geometry name="arm_2_link_5_visual">
        <mesh filename="package://mirror_urdf/meshes/mesh_link5.stl" scale="0.001 0.001 0.001"/>
      </geometry>
      <material name="black"/>
    </visual>
    <collision>
      <origin rpy="0 0 0" xyz="0 0 0"/>
      <geometry name="arm_2_link_5_collision">
        <mesh filename="package://mirror_urdf/meshes/mesh_link5_collision.stl" scale="0.001 0.001 0.001"/>
      </geometry>
    </collision>
  </link>
  <link name="arm_2_link_6">
    <inertial>
      <origin rpy="0 0 0" xyz="-0.0015850697 0.027619818 -0.025442753"/>
      <mass value="1.1947654e+00"/>
      <inertia ixx="0.012632056" ixy="0.00021474114" ixz="0.0001764965" iyy="0.0098149674" iyz="-0.0035702374" izz="0.0072417288"/>
    </inertial>
    <visual>
      <origin rpy="0 0 0" xyz="0 0 0"/>
      <geometry name="arm_2_link_6_visual">
        <mesh filename="package://mirror_urdf/meshes/mesh_link6.stl" scale="0.001 0.001 0.001"/>
      </geometry>
      <material name="black"/>
    </visual>
    <collision>
      <origin rpy="0 0 0" xyz="0 0 0"/>
      <geometry name="arm_2_link_6_collision">
        <box size="0.12 0.12 0.25"/>
        <!-- note: better for simulation -->
      </geometry>
    </collision>
  </link>
  <link name="arm_2_TCP"/>
  <!-- JOINTS MISSING INFO limits friction and damping-->
  <joint name="arm_2_joint_1" type="revolute">
    <parent link="core_link"/>
    <child link="arm_2_link_1"/>
    <origin rpy="0.0 0.0 2.09439510239" xyz="-0.17135 0.29678 0.1338"/>
    <axis xyz="0 0 -1"/>
    <limit effort="200.0" lower="-2.70526034059" upper="2.70526034059" velocity="6.283"/>
    <dynamics damping="3.0" friction="0"/>
  </joint>
  <joint name="arm_2_joint_2" type="revolute">
    <parent link="arm_2_link_1"/>
    <child link="arm_2_link_2"/>
    <origin rpy="0 0 0" xyz="0 0.13166 -0.24966"/>
    <axis xyz="0 1 0"/>
    <limit effort="200.0" lower="-2.70526034059" upper="2.70526034059" velocity="6.283"/>
    <dynamics damping="3.0" friction="0"/>
  </joint>
  <joint name="arm_2_joint_3" type="revolute">
    <parent link="arm_2_link_2"/>
    <child link="arm_2_link_3"/>
    <origin rpy="0 0 0" xyz="0 0 -0.4"/>
    <axis xyz="0 -1 0"/>
    <limit effort="200.0" lower="-2.70526034059" upper="2.70526034059" velocity="6.283"/>
    <dynamics damping="3.0" friction="0"/>
  </joint>
  <joint name="arm_2_joint_4" type="revolute">
    <parent link="arm_2_link_3"/>
    <child link="arm_2_link_4"/>
    <origin rpy="0 0 0" xyz="0 -0.13166 -0.24966"/>
    <axis xyz="0 0 -1"/>
    <limit effort="200.0" lower="-2.70526034059" upper="2.70526034059" velocity="6.283"/>
    <dynamics damping="3.0" friction="0"/>
  </joint>
  <joint name="arm_2_joint_5" type="revolute">
    <parent link="arm_2_link_4"/>
    <child link="arm_2_link_5"/>
    <origin rpy="0 0 0" xyz="0 0.08816 -0.1535"/>
    <axis xyz="0 1 0"/>
    <limit effort="200.0" lower="-1.18682389136" upper="1.18682389136" velocity="6.283"/>
    <dynamics damping="3.0" friction="0"/>
  </joint>
  <joint name="arm_2_joint_6" type="revolute">
    <parent link="arm_2_link_5"/>
    <child link="arm_2_link_6"/>
    <origin rpy="0 0 0" xyz="0 -0.08816 -0.22216"/>
    <axis xyz="0 0 -1"/>
    <limit effort="200.0" lower="-2.70526034059" upper="2.70526034059" velocity="6.283"/>
    <dynamics damping="3.0" friction="0"/>
  </joint>
  <joint name="arm_2_joint_TCP" type="fixed">
    <parent link="arm_2_link_6"/>
    <child link="arm_2_TCP"/>
    <origin rpy="0 0 0" xyz="0 0 -0.14"/>
  </joint>
  <!-- LINKS -->
  <link name="arm_3_link_1">
    <inertial>
      <origin rpy="0 0 0" xyz="0.0013955428 0.025982581 -0.16511476"/>
      <mass value="5.9029271e+00"/>
      <inertia ixx="0.062182861" ixy="8.1614096e-05" ixz="0.00010385066" iyy="0.055346023" iyz="0.01299992" izz="0.016821722"/>
    </inertial>
    <visual>
      <origin rpy="0 0 0" xyz="0 0 0"/>
      <geometry name="arm_3_link_1_visual">
        <mesh filename="package://mirror_urdf/meshes/mesh_link1.stl" scale="0.001 0.001 0.001"/>
      </geometry>
      <material name="black"/>
    </visual>
    <collision>
      <origin rpy="0 0 0" xyz="0 0 0"/>
      <geometry name="arm_3_link_1_collision">
        <mesh filename="package://mirror_urdf/meshes/mesh_link1_collision.stl" scale="0.001 0.001 0.001"/>
      </geometry>
    </collision>
  </link>
  <link name="arm_3_link_2">
    <inertial>
      <origin rpy="0 0 0" xyz="0.0 -0.0071720374 -0.20000694"/>
      <mass value="1.9989653e+00"/>
      <inertia ixx="0.049589547" ixy="-2.3822174e-08" ixz="0.00023476881" iyy="0.051111593" iyz="7.769849e-07" izz="0.0040702979"/>
    </inertial>
    <visual>
      <origin rpy="0 0 0" xyz="0 0 0"/>
      <geometry name="{prefix}_link_2_visual">
        <mesh filename="package://mirror_urdf/meshes/mesh_link2.stl" scale="0.001 0.001 0.001"/>
      </geometry>
      <material name="black"/>
    </visual>
    <collision>
      <origin rpy="0 0 0" xyz="0 0 0"/>
      <geometry name="{prefix}_link_2_collision">
        <mesh filename="package://mirror_urdf/meshes/mesh_link2_collision.stl" scale="0.001 0.001 0.001"/>
      </geometry>
    </collision>
  </link>
  <link name="arm_3_link_3">
    <inertial>
      <origin rpy="0 0 0" xyz="-0.0021052916 -0.10638552 -0.074903486"/>
      <mass value="5.8838845e+00"/>
      <inertia ixx="0.061043599" ixy="-0.00015340891" ixz="-0.0001783316" iyy="0.05360131" iyz="-0.0110909" izz="0.017380798"/>
    </inertial>
    <visual>
      <origin rpy="0 0 0" xyz="0 0 0"/>
      <geometry name="arm_3_link_3_visual">
        <mesh filename="package://mirror_urdf/meshes/mesh_link3.stl" scale="0.001 0.001 0.001"/>
      </geometry>
      <material name="black"/>
    </visual>
    <collision>
      <origin rpy="0 0 0" xyz="0 0 0"/>
      <geometry name="arm_3_link_3_collision">
        <mesh filename="package://mirror_urdf/meshes/mesh_link3_collision.stl" scale="0.001 0.001 0.001"/>
      </geometry>
    </collision>
  </link>
  <link name="arm_3_link_4">
    <inertial>
      <origin rpy="0 0 0" xyz="0.00024496086 -0.0010728501 -0.049015064"/>
      <mass value="1.3982240e+00"/>
      <inertia ixx="0.01466727" ixy="-2.0411012e-05" ixz="-4.476957e-05" iyy="0.0086598581" iyz="-8.3199044e-05" izz="0.010450923"/>
    </inertial>
    <visual>
      <origin rpy="0 0 0" xyz="0 0 0"/>
      <geometry name="arm_3_link_4_visual">
        <mesh filename="package://mirror_urdf/meshes/mesh_link4.stl" scale="0.001 0.001 0.001"/>
      </geometry>
      <material name="black"/>
    </visual>
    <collision>
      <origin rpy="0 0 0" xyz="0 0 0"/>
      <geometry name="arm_3_link_4_collision">
        <mesh filename="package://mirror_urdf/meshes/mesh_link4_collision.stl" scale="0.001 0.001 0.001"/>
      </geometry>
    </collision>
  </link>
  <link name="arm_3_link_5">
    <inertial>
      <origin rpy="0 0 0" xyz="-0.0013228834 -0.08468301 -0.053211105"/>
      <mass value="5.7923846e+00"/>
      <inertia ixx="0.055109543" ixy="-0.00014003837" ixz="0.00021470743" iyy="0.051309424" iyz="-0.0010289246" izz="0.013804762"/>
    </inertial>
    <visual>
      <origin rpy="0 0 0" xyz="0 0 0"/>
      <geometry name="arm_3_link_5_visual">
        <mesh filename="package://mirror_urdf/meshes/mesh_link5.stl" scale="0.001 0.001 0.001"/>
      </geometry>
      <material name="black"/>
    </visual>
    <collision>
      <origin rpy="0 0 0" xyz="0 0 0"/>
      <geometry name="arm_3_link_5_collision">
        <mesh filename="package://mirror_urdf/meshes/mesh_link5_collision.stl" scale="0.001 0.001 0.001"/>
      </geometry>
    </collision>
  </link>
  <link name="arm_3_link_6">
    <inertial>
      <origin rpy="0 0 0" xyz="-0.0015850697 0.027619818 -0.025442753"/>
      <mass value="1.1947654e+00"/>
      <inertia ixx="0.012632056" ixy="0.00021474114" ixz="0.0001764965" iyy="0.0098149674" iyz="-0.0035702374" izz="0.0072417288"/>
    </inertial>
    <visual>
      <origin rpy="0 0 0" xyz="0 0 0"/>
      <geometry name="arm_3_link_6_visual">
        <mesh filename="package://mirror_urdf/meshes/mesh_link6.stl" scale="0.001 0.001 0.001"/>
      </geometry>
      <material name="black"/>
    </visual>
    <collision>
      <origin rpy="0 0 0" xyz="0 0 0"/>
      <geometry name="arm_3_link_6_collision">
        <box size="0.12 0.12 0.25"/>
        <!-- note: better for simulation -->
      </geometry>
    </collision>
  </link>
  <link name="arm_3_TCP"/>
  <!-- JOINTS MISSING INFO limits friction and damping-->
  <joint name="arm_3_joint_1" type="revolute">
    <parent link="core_link"/>
    <child link="arm_3_link_1"/>
    <origin rpy="0.0 0.0 4.18879020479" xyz="-0.17135 -0.29678 0.1338"/>
    <axis xyz="0 0 -1"/>
    <limit effort="200.0" lower="-2.70526034059" upper="2.70526034059" velocity="6.283"/>
    <dynamics damping="3.0" friction="0"/>
  </joint>
  <joint name="arm_3_joint_2" type="revolute">
    <parent link="arm_3_link_1"/>
    <child link="arm_3_link_2"/>
    <origin rpy="0 0 0" xyz="0 0.13166 -0.24966"/>
    <axis xyz="0 1 0"/>
    <limit effort="200.0" lower="-2.70526034059" upper="2.70526034059" velocity="6.283"/>
    <dynamics damping="3.0" friction="0"/>
  </joint>
  <joint name="arm_3_joint_3" type="revolute">
    <parent link="arm_3_link_2"/>
    <child link="arm_3_link_3"/>
    <origin rpy="0 0 0" xyz="0 0 -0.4"/>
    <axis xyz="0 -1 0"/>
    <limit effort="200.0" lower="-2.70526034059" upper="2.70526034059" velocity="6.283"/>
    <dynamics damping="3.0" friction="0"/>
  </joint>
  <joint name="arm_3_joint_4" type="revolute">
    <parent link="arm_3_link_3"/>
    <child link="arm_3_link_4"/>
    <origin rpy="0 0 0" xyz="0 -0.13166 -0.24966"/>
    <axis xyz="0 0 -1"/>
    <limit effort="200.0" lower="-2.70526034059" upper="2.70526034059" velocity="6.283"/>
    <dynamics damping="3.0" friction="0"/>
  </joint>
  <joint name="arm_3_joint_5" type="revolute">
    <parent link="arm_3_link_4"/>
    <child link="arm_3_link_5"/>
    <origin rpy="0 0 0" xyz="0 0.08816 -0.1535"/>
    <axis xyz="0 1 0"/>
    <limit effort="200.0" lower="-1.18682389136" upper="1.18682389136" velocity="6.283"/>
    <dynamics damping="3.0" friction="0"/>
  </joint>
  <joint name="arm_3_joint_6" type="revolute">
    <parent link="arm_3_link_5"/>
    <child link="arm_3_link_6"/>
    <origin rpy="0 0 0" xyz="0 -0.08816 -0.22216"/>
    <axis xyz="0 0 -1"/>
    <limit effort="200.0" lower="-2.70526034059" upper="2.70526034059" velocity="6.283"/>
    <dynamics damping="3.0" friction="0"/>
  </joint>
  <joint name="arm_3_joint_TCP" type="fixed">
    <parent link="arm_3_link_6"/>
    <child link="arm_3_TCP"/>
    <origin rpy="0 0 0" xyz="0 0 -0.14"/>
  </joint>
  <!-- ************ Control frames ************ -->
  <!-- <xacro:include filename="$(find mirror_urdf)/urdf/control_frames.urdf.xacro"/> -->
  <link name="world"/>
  <joint name="reference" type="floating">
    <parent link="world"/>
    <child link="base_link"/>
  </joint>
</robot>
